### Try, Catch e Finally em C#

O tratamento de exceções é uma parte essencial do desenvolvimento de software, pois permite que você lide com erros de maneira controlada e mantenha a aplicação estável. Em C#, o tratamento de exceções é feito através dos blocos `try`, `catch` e `finally`. A seguir, vamos explorar cada um desses conceitos, seus usos e fornecer exemplos práticos.

#### 1. Bloco `try`

O bloco `try` é usado para encapsular o código que pode gerar uma exceção. Se uma exceção ocorrer dentro desse bloco, o controle é transferido para o bloco `catch` correspondente.

#### 2. Bloco `catch`

O bloco `catch` é usado para capturar e tratar a exceção que foi lançada no bloco `try`. Você pode ter múltiplos blocos `catch` para tratar diferentes tipos de exceções.

#### 3. Bloco `finally`

O bloco `finally` é opcional e contém código que será executado independentemente de uma exceção ter ocorrido ou não. É frequentemente usado para liberar recursos, como fechar arquivos ou conexões de banco de dados.

### Estrutura Básica

A estrutura básica do tratamento de exceções em C# é a seguinte:

```csharp
try
{
    // Código que pode gerar uma exceção
}
catch (TipoDaExcecao ex)
{
    // Código para tratar a exceção
}
finally
{
    // Código que sempre será executado
}
```

### Exemplo Prático

Vamos ver um exemplo prático que ilustra o uso de `try`, `catch` e `finally`.

#### Exemplo: Divisão por Zero

```csharp
using System;

public class Program
{
    public static void Main()
    {
        try
        {
            Console.Write("Digite o numerador: ");
            int numerador = int.Parse(Console.ReadLine());
            
            Console.Write("Digite o denominador: ");
            int denominador = int.Parse(Console.ReadLine());
            
            int resultado = numerador / denominador;
            Console.WriteLine($"Resultado: {resultado}");
        }
        catch (DivideByZeroException ex)
        {
            Console.WriteLine("Erro: Não é possível dividir por zero.");
        }
        catch (FormatException ex)
        {
            Console.WriteLine("Erro: O valor digitado não é um número válido.");
        }
        catch (Exception ex)
        {
            Console.WriteLine($"Erro: {ex.Message}");
        }
        finally
        {
            Console.WriteLine("Bloco finally: O programa foi encerrado.");
        }
    }
}
```

### Explicação do Exemplo

1. **Entrada do Usuário**: O programa solicita que o usuário digite um numerador e um denominador.
2. **Divisão**: O código tenta realizar a divisão.
3. **Tratamento de Exceções**:
   - Se o usuário tentar dividir por zero, uma `DivideByZeroException` será lançada, e a mensagem de erro correspondente será exibida.
   - Se o usuário inserir um valor não numérico, uma `FormatException` será lançada.
   - Um bloco `catch` genérico captura qualquer outra exceção que não tenha sido tratada especificamente.
4. **Bloco `finally`**: Este bloco é sempre executado, independentemente de uma exceção ter ocorrido ou não, e exibe uma mensagem final ao usuário.